Workbook

Sheet 總覽
A1: 30 天重建總覽
A2: 先保住資本，再談績效｜所有數字由各紀錄表自動彙總
A4: 核心指標
A5: 目前零下注連續天數 | C5: 每日完成率 | E5: 重訓次數 | G5: 平均衝動
A6: =IF(COUNTA('每日檢核'!$B$5:$B$34)=0,0,INDEX('每日檢核'!$J$5:$J$34,COUNTA('每日檢核'!$B$5:$B$34))) | C6: =COUNTIF('每日檢核'!$B$5:$B$34,"是")/30 | E6: =COUNTIF('每日檢核'!$G$5:$G$34,"是") | G6: =IFERROR(AVERAGE('每日檢核'!$D$5:$D$34),0)
A7: 總訓練組數 | C7: 總訓練量 | E7: 目前現金 | G7: 緩衝達成率
A8: =COUNTA('重訓紀錄'!$C$5:$C$304) | C8: =SUM('重訓紀錄'!$H$5:$H$304) | E8: ='資金控制'!B9 | G8: =MIN('資金控制'!B9/'資金控制'!B7,1)
A10: 今天只做三件事
A11: 1. 封閉資金入口：暫停運彩、終止 Tradeify、刪除 App、移除付款資料與取消盤口內容。
A12: 2. 建立資金防線：設定入薪後自動轉存 80,000 元，寫下『210 萬已結束，不靠下注追回』。
A13: 3. 建立晚間替代：完成第一次全身重訓，寫第一筆日誌，再散步或看一集影集。
A15: 本週檢查
A16: 項目 | B16: 目標 | C16: 目前 | D16: 狀態
A17: 零下注 | B17: 7 天 | C17: ='每週檢討'!D5 | D17: =IF(C17>=7,"達成","未達")
A18: 重訓 | B18: 3 次 | C18: ='每週檢討'!E5 | D18: =IF(C18>=3,"達成","未達")
A19: 散步 | B19: 120 分鐘 | C19: ='每週檢討'!F5 | D19: =IF(C19>=120,"達成","未達")
A20: 日誌 | B20: 7 天 | C20: =COUNTA('每日檢核'!$B$5:$B$11) | D20: =IF(C20>=7,"達成","未達")

Sheet 每日檢核
A1: 30 天每日檢核
A2: 2026-08-04 至 2026-09-02｜空白代表尚未回報，不會自動判定失敗
A4: 日期 | B4: 零下注 | C4: 查看盤口 | D4: 衝動 0–10 | E4: 觸發原因 | F4: 替代行動 | G4: 完成重訓 | H4: 散步分鐘 | I4: 睡眠小時 | J4: 連續零下注
A5: 46238 | B5: 是 | C5: 否 | D5: 0 | G5: =IF(COUNTIF('重訓紀錄'!$A$5:$A$304,A5)>0,"是",IF(B5="","","否")) | H5: 0 | I5: 8 | J5: =IF(B5="","",IF(B5="是",1,0))
A6: 46239 | B6: 是 | C6: 否 | D6: 0 | G6: 否 | H6: 30 | I6: 7.5 | J6: =IF(B6="","",IF(B6="是",J5+1,0))
A7: 46240 | B7: 是 | C7: 否 | D7: 0 | G7: 否 | H7: 30 | I7: 7 | J7: =IF(B7="是",J6+1,0)
A8: 46241 | B8: 是 | C8: 否 | D8: 1 | E8: 看到 DC 群組的運彩分享 | F8: 無 | G8: 否 | H8: 0 | I8: 8 | J8: =IF(B8="是",J7+1,0)
A9: 46242 | B9: 是 | C9: 否 | D9: 0 | G9: 是 | H9: 0 | I9: 10 | J9: =IF(B9="是",J8+1,0)
A10: 46243 | B10: 是 | C10: 否 | D10: 0 | G10: 否 | H10: 15 | I10: 9 | J10: =IF(B10="","",IF(B10="是",J9+1,0))
A11: 46244 | B11: 是 | C11: 否 | D11: 0 | G11: 否 | H11: 20 | I11: 3 | J11: =IF(B11="","",IF(B11="是",J10+1,0))
A12: 46245 | B12: 是 | C12: 否 | D12: 0 | G12: 是 | H12: 0 | I12: 9 | J12: =IF(B12="","",IF(B12="是",J11+1,0))
A13: 46246 | B13: 是 | C13: 否 | D13: 0 | G13: =IF(COUNTIF('重訓紀錄'!$A$5:$A$304,A13)>0,"是",IF(B13="","","否")) | H13: 0 | I13: 3 | J13: =IF(B13="","",IF(B13="是",J12+1,0))
A14: 46247 | B14: 是 | C14: 否 | D14: 0 | G14: 否 | H14: 10 | I14: 6 | J14: =IF(B14="","",IF(B14="是",J13+1,0))
A15: 46248 | B15: 是 | C15: 否 | D15: 0 | G15: =IF(COUNTIF('重訓紀錄'!$A$5:$A$304,A15)>0,"是",IF(B15="","","否")) | H15: 0 | I15: 8 | J15: =IF(B15="","",IF(B15="是",J14+1,0))
A16: 46249 | B16: 是 | C16: 否 | D16: 0 | G16: 否 | H16: 40 | I16: 8 | J16: =IF(B16="","",IF(B16="是",J15+1,0))
A17: 46250 | B17: 是 | C17: 否 | D17: 0 | G17: 否 | H17: 0 | I17: 11 | J17: =IF(B17="","",IF(B17="是",J16+1,0))
A18: 46251 | B18: 是 | C18: 否 | D18: 0 | G18: 否 | H18: 0 | I18: 8 | J18: =IF(B18="","",IF(B18="是",J17+1,0))
A19: 46252 | B19: 是 | C19: 否 | D19: 0 | G19: =IF(COUNTIF('重訓紀錄'!$A$5:$A$304,A19)>0,"是",IF(B19="","","否")) | H19: 30 | I19: 8 | J19: =IF(B19="","",IF(B19="是",J18+1,0))
A20: 46253 | B20: 是 | C20: 否 | D20: 0 | G20: 否 | H20: 0 | I20: 3 | J20: =IF(B20="","",IF(B20="是",J19+1,0))
A21: 46254 | B21: 是 | C21: 否 | D21: 0 | G21: 否 | H21: 30 | I21: 8 | J21: =IF(B21="","",IF(B21="是",J20+1,0))
A22: 46255 | B22: 是 | C22: 否 | D22: 0 | G22: 否 | H22: 0 | I22: 0 | J22: =IF(B22="","",IF(B22="是",J21+1,0))
A23: 46256 | B23: 是 | C23: 否 | D23: 0 | G23: 否 | H23: 0 | I23: 7 | J23: =IF(B23="","",IF(B23="是",J22+1,0))
A24: 46257 | B24: 是 | C24: 否 | D24: 0 | G24: 否 | H24: 0 | I24: 7 | J24: =IF(B24="","",IF(B24="是",J23+1,0))
A25: 46258 | G25: =IF(COUNTIF('重訓紀錄'!$A$5:$A$304,A25)>0,"是",IF(B25="","","否")) | J25: =IF(B25="","",IF(B25="是",J24+1,0))
A26: 46259 | G26: =IF(COUNTIF('重訓紀錄'!$A$5:$A$304,A26)>0,"是",IF(B26="","","否")) | I26: 6 | J26: =IF(B26="","",IF(B26="是",J25+1,0))
A27: 46260 | B27: 是 | C27: 否 | D27: 0 | G27: 否 | H27: 0 | J27: =IF(B27="","",IF(B27="是",J26+1,0))
A28: 46261 | G28: =IF(COUNTIF('重訓紀錄'!$A$5:$A$304,A28)>0,"是",IF(B28="","","否")) | J28: =IF(B28="","",IF(B28="是",J27+1,0))
A29: 46262 | B29: 是 | C29: 否 | D29: 0 | G29: =IF(COUNTIF('重訓紀錄'!$A$5:$A$304,A29)>0,"是",IF(B29="","","否")) | H29: 0 | I29: 2 | J29: =IF(B29="","",IF(B29="是",J28+1,0))
A30: 46263 | G30: 否 | H30: 0 | J30: =IF(B30="","",IF(B30="是",J29+1,0))
A31: 46264 | G31: 否 | H31: 30 | J31: =IF(B31="","",IF(B31="是",J30+1,0))
A32: 46265 | G32: 否 | H32: 0 | J32: =IF(B32="","",IF(B32="是",J31+1,0))
A33: 46266 | G33: 否 | H33: 0 | J33: =IF(B33="","",IF(B33="是",J32+1,0))
A34: 46267 | G34: 否 | H34: 0 | J34: =IF(B34="","",IF(B34="是",J33+1,0))
A36: 準備日基準（不納入 30 天統計）
A37: 日期 | B37: 零下注 | C37: 查看盤口 | D37: 衝動 0–10 | E37: 觸發原因 | F37: 替代行動 | G37: 完成重訓 | H37: 散步分鐘 | I37: 睡眠小時 | J37: 備註
A38: 46237 | B38: 是 | C38: 是 | D38: 3 | E38: 看到 DC 群通知與推薦 | F38: 將運彩下注上限改成 0 | G38: 否 | H38: 15 | I38: 6 | J38: 準備日；不計入正式 30 天完成率。
A39: 46276 | H39: 20

Sheet 重訓紀錄
A1: 逐組重訓紀錄
A2: 啞鈴填單手重量；自重動作重量填 0 並在備註註明「自重」
A4: 日期 | B4: 訓練名稱 | C4: 動作 | D4: 組次 | E4: 重量（kg） | F4: 次數 | G4: DBR | H4: 訓練量 | I4: 備註
A5: 46238 | B5: 重訓 | C5: 睾丸繩下拉 | D5: 1 | E5: 6.25 | F5: 13 | G5: 2 | H5: =IF(OR(E5="",F5=""),"",E5*F5) | I5: 器械刻度確認為 kg；原始重量 6.25 kg；動作名稱照使用者原文。
A6: 46238 | B6: 重訓 | C6: 睾丸繩下拉 | D6: 2 | E6: 6.25 | F6: 11 | G6: 1 | H6: =IF(OR(E6="",F6=""),"",E6*F6) | I6: 器械刻度確認為 kg；原始重量 6.25 kg；動作名稱照使用者原文。
A7: 46238 | B7: 重訓 | C7: 睾丸繩下拉 | D7: 3 | E7: 6.25 | F7: 8 | G7: 1 | H7: =IF(OR(E7="",F7=""),"",E7*F7) | I7: 器械刻度確認為 kg；原始重量 6.25 kg；動作名稱照使用者原文。
A8: 46238 | B8: 重訓 | C8: 睾丸繩下拉 | D8: 4 | E8: 6.25 | F8: 5 | G8: 1 | H8: =IF(OR(E8="",F8=""),"",E8*F8) | I8: 器械刻度確認為 kg；原始重量 6.25 kg；動作名稱照使用者原文。
A9: 46238 | B9: 重訓 | C9: 腿推舉 | D9: 1 | E9: 40 | F9: 16 | G9: 3 | H9: =IF(OR(E9="",F9=""),"",E9*F9) | I9: 器械雙刻度確認：原回報 80 為 lb，同一插銷位置對應機台標示 40 kg；原回報剩餘 3 下（RIR 3），換算 RPE 7。
A10: 46238 | B10: 重訓 | C10: 腿推舉 | D10: 2 | E10: 40 | F10: 18 | G10: 2 | H10: =IF(OR(E10="",F10=""),"",E10*F10) | I10: 器械雙刻度確認：原回報 80 為 lb，同一插銷位置對應機台標示 40 kg；原回報剩餘 2 下（RIR 2），換算 RPE 8。
A11: 46238 | B11: 重訓 | C11: 腿推舉 | D11: 3 | E11: 40 | F11: 16 | G11: 1 | H11: =IF(OR(E11="",F11=""),"",E11*F11) | I11: 器械雙刻度確認：原回報 80 為 lb，同一插銷位置對應機台標示 40 kg；原回報剩餘 1 下（RIR 1），換算 RPE 9。
A12: 46238 | B12: 重訓 | C12: 腿推舉 | D12: 4 | E12: 40 | F12: 16 | G12: 0 | H12: =IF(OR(E12="",F12=""),"",E12*F12) | I12: 器械雙刻度確認：原回報 80 為 lb，同一插銷位置對應機台標示 40 kg；原回報剩餘 0 下（RIR 0），換算 RPE 10。
A13: 46238 | B13: 重訓 | C13: 蝴蝶機夾胸 | D13: 1 | E13: 25 | F13: 14 | G13: 0 | H13: =IF(OR(E13="",F13=""),"",E13*F13) | I13: 依照片辨識為坐姿胸推；原填 RPE 0 已更正為 RPE 10。
A14: 46238 | B14: 重訓 | C14: 蝴蝶機夾胸 | D14: 2 | E14: 25 | F14: 9 | G14: 0 | H14: =IF(OR(E14="",F14=""),"",E14*F14) | I14: 依照片辨識為坐姿胸推；原填 RPE 0 已更正為 RPE 10。
A15: 46238 | B15: 重訓 | C15: 蝴蝶機夾胸 | D15: 3 | E15: 20 | F15: 13 | G15: 0 | H15: =IF(OR(E15="",F15=""),"",E15*F15) | I15: 依照片辨識為坐姿胸推；原填 RPE 0 已更正為 RPE 10。
A16: 46238 | B16: 重訓 | C16: 蝴蝶機夾胸 | D16: 4 | E16: 20 | F16: 10 | G16: 0 | H16: =IF(OR(E16="",F16=""),"",E16*F16) | I16: 依照片辨識為坐姿胸推；原填 RPE 0 已更正為 RPE 10。
A17: 46238 | B17: 重訓 | C17: 腿後勾 | D17: 1 | E17: 32 | F17: 15 | G17: 5 | H17: =IF(OR(E17="",F17=""),"",E17*F17) | I17: 使用者確認為標準 RPE 5。
A18: 46238 | B18: 重訓 | C18: 腿後勾 | D18: 2 | E18: 40 | F18: 15 | G18: 1 | H18: =IF(OR(E18="",F18=""),"",E18*F18)
A19: 46238 | B19: 重訓 | C19: 腿後勾 | D19: 3 | E19: 40 | F19: 15 | G19: 0 | H19: =IF(OR(E19="",F19=""),"",E19*F19)
A20: 46238 | B20: 重訓 | C20: 腿後勾 | D20: 4 | E20: 40 | F20: 17 | G20: 0 | H20: =IF(OR(E20="",F20=""),"",E20*F20) | I20: 原填 RPE 0，使用者更正為 RPE 10。
A21: 46238 | B21: 重訓 | C21: 腿後勾 | D21: 5 | E21: 32 | F21: 20 | G21: 0 | H21: =IF(OR(E21="",F21=""),"",E21*F21)
A22: 46242 | B22: 重訓 | C22: 上斜胸推 | D22: 1 | E22: 25 | F22: 15 | G22: 2 | H22: =E22*F22
A23: 46242 | B23: 重訓 | C23: 上斜胸推 | D23: 2 | E23: 25 | F23: 14 | G23: 0 | H23: =E23*F23
A24: 46242 | B24: 重訓 | C24: 上斜胸推 | D24: 3 | E24: 25 | F24: 10 | G24: 0 | H24: =E24*F24
A25: 46242 | B25: 重訓 | C25: 上斜胸推 | D25: 4 | E25: 20 | F25: 10 | G25: 0 | H25: =E25*F25
A26: 46242 | B26: 重訓 | C26: 臀推機 | D26: 1 | E26: 20 | F26: 13 | G26: 6 | H26: =E26*F26
A27: 46242 | B27: 重訓 | C27: 臀推機 | D27: 2 | E27: 20 | F27: 15 | G27: 2 | H27: =E27*F27
A28: 46242 | B28: 重訓 | C28: 臀推機 | D28: 3 | E28: 20 | F28: 15 | G28: 2 | H28: =E28*F28
A29: 46242 | B29: 重訓 | C29: 臀推機 | D29: 4 | E29: 20 | F29: 15 | G29: 1 | H29: =E29*F29
A30: 46242 | B30: 重訓 | C30: 滑輪下拉 | D30: 1 | E30: 37.5 | F30: 15 | G30: 3 | H30: =E30*F30
A31: 46242 | B31: 重訓 | C31: 滑輪下拉 | D31: 2 | E31: 37.5 | F31: 12 | G31: 0 | H31: =E31*F31
A32: 46242 | B32: 重訓 | C32: 滑輪下拉 | D32: 3 | E32: 30 | F32: 16 | G32: 2 | H32: =E32*F32
A33: 46242 | B33: 重訓 | C33: 滑輪下拉 | D33: 4 | E33: 30 | F33: 14 | G33: 1 | H33: =E33*F33
... A37: 46242 | B37: 重訓 | C37: 腿外展 | D37: 2 | E37: 52.5 | F37: 13 | G37: 2 | H37: =E37*F37
A38: 46245 | B38: 重訓 | C38: 羅馬尼亞蹲 | D38: 1 | E38: 0 | F38: 13 | G38: 5 | H38: =IF(OR(E38="",F38=""),"",E38*F38) | I38: 自重；使用者回報 DBR 5，未視為 RPE。
A39: 46245 | B39: 重訓 | C39: 羅馬尼亞蹲 | D39: 2 | E39: 0 | F39: 15 | G39: 3 | H39: =IF(OR(E39="",F39=""),"",E39*F39) | I39: 自重；使用者回報 DBR 3，未視為 RPE。
A40: 46245 | B40: 重訓 | C40: 羅馬尼亞蹲 | D40: 3 | E40: 5 | F40: 13 | G40: 2 | H40: =IF(OR(E40="",F40=""),"",E40*F40) | I40: 額外加重 5 kg；使用者回報 DBR 2，未視為 RPE。
A41: 46245 | B41: 重訓 | C41: 羅馬尼亞蹲 | D41: 4 | E41: 5 | F41: 14 | G41: 2 | H41: =IF(OR(E41="",F41=""),"",E41*F41) | I41: 額外加重 5 kg；使用者回報 DBR 2，未視為 RPE。
A42: 46245 | B42: 重訓 | C42: 划船 | D42: 1 | E42: 22.5 | F42: 15 | G42: 5 | H42: =IF(OR(E42="",F42=""),"",E42*F42) | I42: DBR 5
A43: 46245 | B43: 重訓 | C43: 划船 | D43: 2 | E43: 30 | F43: 13 | G43: 5 | H43: =IF(OR(E43="",F43=""),"",E43*F43) | I43: DBR 5
A44: 46245 | B44: 重訓 | C44: 划船 | D44: 3 | E44: 30 | F44: 16 | G44: 2 | H44: =IF(OR(E44="",F44=""),"",E44*F44) | I44: DBR 2
...

Sheet 資金控制
A1: 資金控制
A2: 只記總額，不保存銀行帳號、信用卡號或登入資訊
A4: 基準項目 | B4: 金額（TWD）
A5: 起始現金 | B5: 20000
A6: 投資資產（基準） | B6: 1030000
A7: 現金緩衝目標 | B7: 121200
A8: 入薪轉存目標 | B8: 80000
A9: 目前現金 | B9: =B5+SUM(B14:B25)
A10: 距離目標 | B10: =B7-B9
A12: 轉存紀錄
A13: 日期 | B13: 金額（TWD） | C13: 備註
A14: 46239 | B14: 50000 | C14: 薪資入帳 133,735 元；轉入現金緩衝
A27: 每週資產核對
A28: 核對日 | B28: 現金 | C28: 投資資產 | D28: 負債 | E28: 備註
A29: 46243
A30: 46250
A31: 46257
A32: 46264
A33: 46267
A35: 資料來源：使用者於 2026-08-03 對話提供。210 萬歷史損失不列為待追回資產；本表只追蹤未來資金控制。

Sheet 每週檢討
A1: 每週檢討
A2: 第 4 週涵蓋最後 9 天；黃色欄位由你自行填寫
A4: 週期 | B4: 開始日 | C4: 結束日 | D4: 零下注天數 | E4: 重訓次數 | F4: 散步分鐘 | G4: 平均衝動 | H4: 違規次數 | I4: 本週最強觸發 | J4: 有效替代方法 | K4: 下週修正
A5: 第 1 週 | B5: 46238 | C5: 46244 | D5: =COUNTIFS('每日檢核'!$A$5:$A$34,">="&B5,'每日檢核'!$A$5:$A$34,"<="&C5,'每日檢核'!$B$5:$B$34,"是") | E5: =COUNTIFS('每日檢核'!$A$5:$A$34,">="&B5,'每日檢核'!$A$5:$A$34,"<="&C5,'每日檢核'!$G$5:$G$34,"是") | F5: =SUMIFS('每日檢核'!$H$5:$H$34,'每日檢核'!$A$5:$A$34,">="&B5,'每日檢核'!$A$5:$A$34,"<="&C5) | G5: =IFERROR(AVERAGEIFS('每日檢核'!$D$5:$D$34,'每日檢核'!$A$5:$A$34,">="&B5,'每日檢核'!$A$5:$A$34,"<="&C5),0) | H5: =COUNTIFS('每日檢核'!$A$5:$A$34,">="&B5,'每日檢核'!$A$5:$A$34,"<="&C5,'每日檢核'!$B$5:$B$34,"否")+COUNTIFS('每日檢核'!$A$5:$A$34,">="&B5,'每日檢核'!$A$5:$A$34,"<="&C5,'每日檢核'!$C$5:$C$34,"是")
A6: 第 2 週 | B6: 46245 | C6: 46251 | D6: =COUNTIFS('每日檢核'!$A$5:$A$34,">="&B6,'每日檢核'!$A$5:$A$34,"<="&C6,'每日檢核'!$B$5:$B$34,"是") | E6: =COUNTIFS('每日檢核'!$A$5:$A$34,">="&B6,'每日檢核'!$A$5:$A$34,"<="&C6,'每日檢核'!$G$5:$G$34,"是") | F6: =SUMIFS('每日檢核'!$H$5:$H$34,'每日檢核'!$A$5:$A$34,">="&B6,'每日檢核'!$A$5:$A$34,"<="&C6) | G6: =IFERROR(AVERAGEIFS('每日檢核'!$D$5:$D$34,'每日檢核'!$A$5:$A$34,">="&B6,'每日檢核'!$A$5:$A$34,"<="&C6),0) | H6: =COUNTIFS('每日檢核'!$A$5:$A$34,">="&B6,'每日檢核'!$A$5:$A$34,"<="&C6,'每日檢核'!$B$5:$B$34,"否")+COUNTIFS('每日檢核'!$A$5:$A$34,">="&B6,'每日檢核'!$A$5:$A$34,"<="&C6,'每日檢核'!$C$5:$C$34,"是")
A7: 第 3 週 | B7: 46252 | C7: 46258 | D7: =COUNTIFS('每日檢核'!$A$5:$A$34,">="&B7,'每日檢核'!$A$5:$A$34,"<="&C7,'每日檢核'!$B$5:$B$34,"是") | E7: =COUNTIFS('每日檢核'!$A$5:$A$34,">="&B7,'每日檢核'!$A$5:$A$34,"<="&C7,'每日檢核'!$G$5:$G$34,"是") | F7: =SUMIFS('每日檢核'!$H$5:$H$34,'每日檢核'!$A$5:$A$34,">="&B7,'每日檢核'!$A$5:$A$34,"<="&C7) | G7: =IFERROR(AVERAGEIFS('每日檢核'!$D$5:$D$34,'每日檢核'!$A$5:$A$34,">="&B7,'每日檢核'!$A$5:$A$34,"<="&C7),0) | H7: =COUNTIFS('每日檢核'!$A$5:$A$34,">="&B7,'每日檢核'!$A$5:$A$34,"<="&C7,'每日檢核'!$B$5:$B$34,"否")+COUNTIFS('每日檢核'!$A$5:$A$34,">="&B7,'每日檢核'!$A$5:$A$34,"<="&C7,'每日檢核'!$C$5:$C$34,"是")
A8: 第 4 週 | B8: 46259 | C8: 46267 | D8: =COUNTIFS('每日檢核'!$A$5:$A$34,">="&B8,'每日檢核'!$A$5:$A$34,"<="&C8,'每日檢核'!$B$5:$B$34,"是") | E8: =COUNTIFS('每日檢核'!$A$5:$A$34,">="&B8,'每日檢核'!$A$5:$A$34,"<="&C8,'每日檢核'!$G$5:$G$34,"是") | F8: =SUMIFS('每日檢核'!$H$5:$H$34,'每日檢核'!$A$5:$A$34,">="&B8,'每日檢核'!$A$5:$A$34,"<="&C8) | G8: =IFERROR(AVERAGEIFS('每日檢核'!$D$5:$D$34,'每日檢核'!$A$5:$A$34,">="&B8,'每日檢核'!$A$5:$A$34,"<="&C8),0) | H8: =COUNTIFS('每日檢核'!$A$5:$A$34,">="&B8,'每日檢核'!$A$5:$A$34,"<="&C8,'每日檢核'!$B$5:$B$34,"否")+COUNTIFS('每日檢核'!$A$5:$A$34,">="&B8,'每日檢核'!$A$5:$A$34,"<="&C8,'每日檢核'!$C$5:$C$34,"是")

Sheet 規則與身份
A1: 規則與身份
A2: 這一頁不是勵志語錄；它是復發時必須照做的決策邊界
A4: 身份重建
A5: 舊身份 | B5: 我夠聰明，可以私下把損失贏回來；只要還有翻本機會，就不必承認失控。
A6: 五年反願景 | B6: 40 歲仍靠下注取得刺激、資產停滯並繼續隱瞞損失，睡前問自己：我到底在幹嘛？
A7: 新身份 | B7: 我是用可驗證行為保護資本的人；刺激不能碰我的資產。
A8: 30 天唯一目標 | B8: 連續 30 天不以真錢滿足翻本衝動，重新取得對資金與晚間生活的控制。
A10: 不可談判規則
A11: 1. 運彩、期貨實盤、prop firm 帳號、充值與替代帳戶交易全部為零。
A12: 2. 不主動查看盤口、預測推文、交易直播或請 AI 分析勝率。
A13: 3. 210 萬是已結束的代價，不設定追回期限。
A14: 4. 入薪後轉存 80,000 元；現金緩衝先達到 121,200 元。
A15: 5. 任何一次下注都算違規，不追損、不重寫規則，剩餘天數仍繼續執行。
A17: 明日三件事
A18: 1. 封閉資金入口：暫停運彩、終止 Tradeify、刪除 App、移除付款資料與取消盤口內容。
A19: 2. 建立資金防線：設定入薪後自動轉存 80,000 元，寫下『210 萬已結束，不靠下注追回』。
A20: 3. 建立晚間替代：完成第一次全身重訓，寫第一筆日誌，再散步或看一集影集。
A22: 違規處理與求助
A23: 立即停止，不追損；記錄金額、觸發點與使用管道。
... A26: 官方節制投注資料：https://article.sportslottery.com.tw/zh-tw/declaration/98?iframe

Sheet 飲食紀錄
A1: 飲食紀錄
A2: 只記實際吃的內容；未提供份量、飽足感或熱量時保持空白，不自行猜測
A4: 日期 | B4: 餐別 | C4: 餐廳／來源 | D4: 餐點內容 | E4: 蛋白質（g） | F4: 熱量（kcal） | G4: 備註 | H4: 碳水（g）
A5: 46237 | B5: 早餐 | D5: 培根蛋吐司、雞塊 | E5: 30 | F5: 750 | G5: 估算：早餐店培根蛋吐司＋一份雞塊；實際份量未提供。 碳水估算：吐司與雞塊裹粉合計約 65 g。 | H5: 65
A6: 46237 | B6: 午餐 | D6: 未進食 | E6: 0 | F6: 0 | H6: 0
A7: 46237 | B7: 晚餐 | C7: 樂晴牛排館 | D7: 牛排、雞排、酥皮濃湯 | E7: 95 | F7: 1450 | G7: 估算：樂晴牛排館雙排餐＋酥皮濃湯；依常見份量計。 碳水估算：主要來自酥皮濃湯，未另計醬料。 | H7: 45
A8: 46238 | B8: 早餐 | C8: 7-ELEVEN（711） | D8: 地瓜、海鹽水煮蛋、雞胸肉 | E8: 33 | F8: 300 | G8: 估算：7-ELEVEN 地瓜＋水煮蛋＋雞胸；實際品項份量未提供。 碳水估算：主要來自地瓜。 | H8: 35
A9: 46238 | B9: 午餐 | C9: 麥當勞 | D9: 大麥克、無糖可樂、小杯玉米湯、中薯 | E9: 30 | F9: 1042 | G9: 麥當勞營養資料估算：大麥克、中薯、小杯玉米湯、無糖可樂。 碳水估算：大麥克、中薯與小杯玉米湯合計約 120 g。 | H9: 120
A10: 46238 | B10: 晚餐 | D10: 雙倍雞肉飯，飯一半 | E10: 65 | F10: 850 | G10: 使用者回報：850 kcal、蛋白質 65 g。 碳水估算：主要來自半份白飯。 | H10: 55
A11: 46239 | B11: 早餐 | C11: 7-ELEVEN（711） | D11: 御選肉鬆飯糰、雙蔬鮪魚飯糰 | E11: 10.7 | F11: 485 | G11: 包裝營養標示合計：251＋234 kcal；蛋白質 5.5＋5.2 g。 碳水估算：兩顆飯糰合計約 90 g。 | H11: 90
A12: 46239 | B12: 午餐 | D12: 未進食 | E12: 0 | F12: 0 | H12: 0
A13: 46239 | B13: 晚餐 | C13: 鐵板燒 | D13: 松阪豬、嫩煎豆腐、豆芽菜、高麗菜、豆漿 | E13: 51 | F13: 714 | G13: 估算：鐵板燒松阪豬、豆腐、兩樣蔬菜與一瓶豆漿；豆漿採 144 kcal。 碳水估算：主要來自豆漿與蔬菜，未另計醬汁。 | H13: 28
A14: 46240 | B14: 早餐 | C14: 全家便利商店 | D14: 豆漿、地瓜、雞胸肉 | E14: 40 | F14: 394 | G14: 估算：全家豆漿、地瓜、雞胸；豆漿採使用者提供的 144 kcal。 碳水估算：地瓜約 35 g、豆漿約 13 g。 | H14: 48
A15: 46240 | B15: 午餐 | D15: 乳清蛋白粉 40g | E15: 30 | F15: 160 | G15: 估算：未提供品牌營養標示，按乳清粉 40g 約含蛋白質 30g、160 kcal 計。 碳水估算：未提供品牌，按一般乳清粉估算。 | H15: 4
A16: 46240 | B16: 晚餐 | D16: 炸雞排、炸杏鮑菇、炸魷魚 | E16: 54 | F16: 1054 | G16: 估算：炸雞排 630、炸杏鮑菇 174、炸魷魚 250 kcal；實際份量與裹粉用油不同會有差異。 碳水估算：主要來自裹粉。 | H16: 70
A17: 46241 | B17: 早餐 | D17: 地瓜、雞胸肉 | E17: 27 | F17: 250 | G17: 估算：依固定設定；地瓜 2g 蛋白質、雞胸肉 25g 蛋白質。 碳水估算：主要來自地瓜。 | H17: 35
A18: 46241 | B18: 午餐 | D18: 乳清蛋白粉 40g | E18: 30 | F18: 160 | G18: 估算：未提供品牌營養標示，按乳清粉 40g 約含蛋白質 30g、160 kcal 計。 碳水估算：未提供品牌，按一般乳清粉估算。 | H18: 4
A19: 46241 | B19: 晚餐 | C19: 火鍋 | D19: 肉片約 15 片、蔬菜 | E19: 45 | F19: 650 | G19: 估算：未提供肉種與重量，按一般火鍋肉片約 225g 加蔬菜計。 碳水估算：主要來自蔬菜與湯底，未另計醬料。 | H19: 15
A20: 46242 | B20: 早餐 | D20: 地瓜、雞胸肉 | E20: 32 | F20: 285 | G20: 雞胸肉蛋白質採使用者回報 30g；地瓜沿用 2g。熱量按一般份量估算。 碳水估算：主要來自地瓜。 | H20: 35
A21: 46242 | B21: 午餐 | D21: 乳清蛋白粉 60g、豆漿 | E21: 58 | F21: 384 | G21: 乳清按 60g 粉估算蛋白質 45g、240 kcal；豆漿沿用 13g、144 kcal。 碳水估算：乳清約 6 g、豆漿約 13 g。 | H21: 19
A22: 46242 | B22: 晚餐 | C22: 好食多涮涮鍋 | D22: 昆布鍋、12 盎司增肌減脂肉片、活鮑魚 3 個、白飯 1 碗 | E22: 82 | F22: 850 | G22: 估算：12 盎司約 340g。肉種與醬料未提供；依低脂火鍋肉片、鮑魚與白飯估算，未另計菜盤。 碳水估算：白飯約 60 g，加菜盤與湯底約 10 g。 | H22: 70
A105: 46242 | B105: 晚餐 | D105: 40g 乳清 + 1 杯豆漿 | E105: 43 | F105: 304 | G105: 晚餐後；未提供乳清品牌/營養標示與豆漿品牌/容量，蛋白質與熱量待補。 估算：沿用既有假設，40 g 乳清約蛋白質 30 g、160 kcal、碳水 4 g；豆漿約蛋白質 13 g、144 kcal、碳水 13 g。 | H105: 17
A106: 46243 | B106: 早餐 | C106: 7-ELEVEN（溏心蛋） | D106: 地瓜 + 7-ELEVEN 溏心蛋 2 顆 + 雞胸肉 | E106: 42.8 | F106: 391 | G106: 估算：地瓜與雞胸肉沿用 2026-08-08 早餐設定（蛋白質 32 g、熱量 285 kcal、碳水 35 g）；7-ELEVEN 溏心蛋每顆以蛋白質 5.4 g、熱量 53 kcal、碳水 1.4 g 估算。 | H106: 37.8
A107: 46243 | B107: 晚餐 | D107: 雞排 + 鰻魚 + 豆干 + 空心菜 + 豆腐 + 滷蛋 1 顆 + 素肚 | E107: 95 | F107: 1250 | G107: 依照片估算：一份炸雞排、鰻魚、豆干、空心菜、豆腐、滷蛋與素肚；實際份量、醬汁與用油未提供，營養數值為整盤估算。 蛋白質依使用者確認改採較保守估算 95 g。 | H107: 55
A108: 46243 | B108: 午餐 | C108: 使用者回報 | D108: 未進食 | G108: 使用者明確回報午餐未進食。
A109: 46244 | B109: 早餐 | D109: 地瓜 | E109: 2 | F109: 125 | G109: 估算：沿用先前地瓜固定設定，約蛋白質 2 g、碳水 35 g、125 kcal。 | H109: 35
A110: 46244 | B110: 午餐 | D110: 豆漿 + 乳清蛋白粉 60g | E110: 58 | F110: 384 | G110: 估算：沿用 2026-08-08 相同組合設定；乳清 60 g 約蛋白質 45 g、240 kcal、碳水 6 g；豆漿約蛋白質 13 g、144 kcal、碳水 13 g。 | H110: 19
A111: 46244 | B111: 晚餐 | D111: 牛肉飯 特大碗（飯一半） + 乳清蛋白粉 60g + 豆漿 | E111: 93 | F111: 1184 | G111: 估算：牛肉飯為特大碗但白飯實際吃約一半，先估蛋白質 35 g、碳水 60 g、800 kcal；乳清 60 g + 豆漿沿用既有設定，約蛋白質 58 g、碳水 19 g、384 kcal。合計約蛋白質 93 g、碳水 79 g、1184 kcal；店家、實際牛肉量與乳清/豆漿品牌未提供。 | H111: 79
A112: 46245 | B112: 早餐 | D112: 豆漿 + 乳清蛋白粉 40g + 地瓜 | E112: 45 | F112: 429 | G112: 估算：沿用既有設定；乳清蛋白粉 40 g 約蛋白質 30 g、碳水 4 g、160 kcal；豆漿約蛋白質 13 g、碳水 13 g、144 kcal；地瓜約蛋白質 2 g、碳水 35 g、125 kcal。合計約蛋白質 45 g、碳水 52 g、429 kcal；品牌與實際份量未提供。 | H112: 52
A113: 46245 | B113: 晚餐 | D113: 運動前：豆漿 + 乳清蛋白粉 40g | E113: 43 | F113: 304 | G113: 估算沿用既有設定：乳清蛋白粉 40g 約蛋白質 30g、碳水 4g、160 kcal；豆漿約蛋白質 13g、碳水 13g、144 kcal。 | H113: 17
A114: 46245 | B114: 晚餐 | D114: 雙倍雞肉飯 | E114: 65 | F114: 1050 | G114: 估算：沿用先前雙倍雞肉飯的雞肉份量設定，這次未註明飯減半，因此按完整一份白飯估算；約蛋白質 65 g、碳水 95 g、1050 kcal。實際醬汁與用油可能造成誤差。 | H114: 95
A115: 46245 | B115: 午餐 | C115: 使用者回報 | D115: 未進食 | G115: 使用者明確回報午餐未進食。
A116: 46246 | B116: 早餐 | C116: 使用者回報 | D116: 地瓜 + 豆漿 + 乳清蛋白粉 40g | E116: 45 | F116: 429 | G116: 估算沿用既有設定：乳清蛋白粉 40g 約蛋白質 30g、碳水 4g、160 kcal；豆漿約蛋白質 13g、碳水 13g、144 kcal；地瓜約蛋白質 2g、碳水 35g、125 kcal。 | H116: 52
A117: 46246 | B117: 午餐 | C117: 使用者回報 | D117: 黑咖啡 1 杯 | E117: 0 | F117: 0 | G117: 按無糖、無奶黑咖啡記錄；熱量視為可忽略。 | H117: 0
A118: 46246 | B118: 晚餐 | C118: 公開資料估算（FatSecret；商品版本可能不同） | D118: 全家 健身G肉餐盒 | E118: 29 | F118: 500 | G118: 採公開完整營養資料：每份約蛋白質 29 g、碳水 67.7 g、500 kcal。另有近期商品分享標示 385 g／481 kcal，推測版本或配方不同，因此本筆為透明估算。 | H118: 67.7
A119: 46246 | B119: 晚餐 | C119: 估算 | D119: 乳清蛋白粉 40g | E119: 32 | F119: 160 | G119: 未提供品牌與營養標示；以一般乳清蛋白粉約每 40 g 含蛋白質 32 g、碳水 4 g、160 kcal 估算。 | H119: 4
A120: 46246 | B120: 晚餐 | C120: 使用者回報 | D120: 豆漿 | G120: 品牌、容量與營養標示未提供；依規則不猜份量，蛋白質、碳水與熱量暫留空白待補。
A121: 46247 | B121: 早餐 | C121: 使用者回報 | D121: 豆漿 + 乳清蛋白粉 40g + 雞胸肉 + 地瓜 | E121: 75 | F121: 589 | G121: 估算沿用既有設定：豆漿約蛋白質 13g、碳水 13g、144 kcal；乳清蛋白粉 40g 約蛋白質 30g、碳水 4g、160 kcal；雞胸肉依使用者回報蛋白質 30g，沿用既有份量估算約 160 kcal；地瓜約蛋白質 2g、碳水 35g、125 kcal。 | H121: 52
A122: 46247 | B122: 晚餐 | C122: 使用者回報 | D122: 牛腩咖哩 + 雞腿肉 1 份 + 番茄 + 豆漿 + 乳清蛋白粉 40g | E122: 114 | F122: 1549 | G122: 修正估算：使用者補充白飯份量可能接近兩份且份量偏多。原估算上額外加約 1 碗白飯（蛋白質約 5g、碳水約 60g、280 kcal）。其餘牛腩咖哩、雞腿肉、番茄、豆漿與乳清沿用先前估算。 | H122: 157
A123: 46247 | B123: 午餐 | C123: 使用者回報 | D123: 未進食 | G123: 使用者明確回報午餐未進食。
...

Sheet 營養設定
A1: 營養設定
A2: 以下為你指定的固定蛋白質估算；未設定食物保持空白，不自行推估。
A4: 食物 | B4: 蛋白質（g） | C4: 熱量（kcal） | D4: 套用說明
A5: 豆漿 | B5: 13 | C5: 144 | D5: 每瓶／份
A6: 地瓜 | B6: 2 | D6: 每份
A7: 雞胸肉 | B7: 25 | D7: 每份
A8: 牛排 | B8: 50 | D8: 每份
A9: 雞腿排 | B9: 45 | D9: 每份
A10: 雞排（視為雞腿排） | B10: 45 | D10: 用於舊紀錄；可依實際品項更正
A11: 大麥克 | B11: 26 | D11: 每份
A13: 既有飲食：已設定蛋白質每日小計
A14: 日期 | B14: 蛋白質（g） | C14: 說明
A15: 46237 | B15: =SUMIF('飲食紀錄'!$A$5:$A$94,A15,'飲食紀錄'!$E$5:$E$94) | C15: 僅合計已設定食物
A16: 46238 | B16: =SUMIF('飲食紀錄'!$A$5:$A$94,A16,'飲食紀錄'!$E$5:$E$94) | C16: 僅合計已設定食物
A17: 46239 | B17: =SUMIF('飲食紀錄'!$A$5:$A$94,A17,'飲食紀錄'!$E$5:$E$94) | C17: 僅合計已設定食物
A18: 46240 | B18: =SUMIF('飲食紀錄'!$A$5:$A$94,A18,'飲食紀錄'!$E$5:$E$94) | C18: 僅合計已設定食物
A19: 46241 | B19: 102 | C19: 僅合計已設定食物
A20: 46242 | B20: 172 | C20: 早餐 32g＋午餐 58g＋晚餐 82g；蛋白質合計

Sheet 營養來源
A1: 營養估算來源
A2: 黃色為依餐點或通用份量的估算；綠色為官方、包裝標示或使用者提供數字。
A4: 日期／餐別 | B4: 資料類型 | C4: 來源 | D4: 用途
A5: 2026-08-03 早餐 | B5: 通用估算 | C5: https://meals.ntu.edu.tw/CampusDining/kcal/breakfast | D5: 培根蛋三明治熱量基準；雞塊按常見一份估算
A6: 2026-08-03 晚餐 | B6: 餐廳菜單＋通用估算 | C6: https://www.ubereats.com/tw/store/%E6%A8%82%E6%99%B4%E7%89%9B%E6%8E%92%E9%A4%A8/ilGt4LRHXgmSOVWjMT71Eg | D6: 樂晴牛排館品項描述；雙排餐份量估算
A7: 2026-08-04 早餐 | B7: 通用估算 | C7: https://www.7-11.com.tw/freshfoods/4_snacks/index.aspx | D7: 7-ELEVEN 類似品項與一般份量
A8: 2026-08-04 午餐 | B8: 官方／公開營養資料 | C8: https://www.mcdonalds.com/tw/zh-tw/sustainability/good-food/nutrition.html | D8: 大麥克、中薯、小杯玉米湯、無糖可樂
A9: 2026-08-04 晚餐 | B9: 使用者提供 | C9: 使用者回報 | D9: 850 kcal、蛋白質 65 g
A10: 2026-08-05 早餐／晚餐 | B10: 包裝標示／通用估算 | C10: 包裝照片；https://www.fda.gov.tw/tc/site.aspx?r=1003484775&sid=271 | D10: 飯糰採包裝標示；鐵板燒採通用份量估算
A11: 2026-08-06 早餐 | B11: 通用估算 | C11: https://www.fda.gov.tw/tc/site.aspx?r=1003484775&sid=271 | D11: 全家豆漿、地瓜、雞胸採一般份量估算
A12: 2026-08-06 午餐 | B12: 通用估算 | C12: 使用者回報，未提供品牌或標示 | D12: 乳清粉 40g 暫以蛋白質 30g、160 kcal 計
A13: 2026-08-06 晚餐 | B13: 通用估算 | C13: https://health.tvbs.com.tw/nutrition/351544；https://www.mos.com.tw/menu/Detail.aspx?id=M001236 | D13: 炸雞排、炸杏鮑菇與炸魷魚的公開熱量資料；蛋白質依一般份量估算
A14: 2026-08-07 三餐 | B14: 通用估算 | C14: https://www.fda.gov.tw/tc/site.aspx?r=1003484775&sid=271 | D14: 早餐、乳清與火鍋肉片依既有設定或一般份量估算
A15: 2026-08-08 早餐／晚餐 | B15: 使用者回報＋既有設定 | C15: 使用者回報 | D15: 雞胸肉 30g 蛋白質；乳清 60g 粉與豆漿依既有比例估算
... A17: 2026-08-08 晚餐 | B17: 好食多涮涮鍋資訊＋使用者回報 | C17: https://www.fonfood.com/store/416083 | D17: 昆布鍋與肉盤份量參考；12 盎司、鮑魚與白飯由使用者回報。無公開營養標示，故熱量與蛋白質採估算。

Sheet 有氧紀錄
A1: 日期 | B1: 有氧類型 | C1: 段次 | D1: 時間（分鐘） | E1: 坡度（%） | F1: 速度（km/h） | G1: 距離（km） | H1: 備註
A2: 46262 | B2: 跑步機爬坡 | C2: 1 | D2: 20 | E2: 12 | F2: 4.1 | H2: 使用者回報：爬坡坡度 12、速度 4.1 km/h、20 分鐘；獨立記錄，不併入散步分鐘。
A3: 46267 | B3: 跑步機爬坡 | C3: 1 | D3: 30 | E3: 12 | F3: 4.1 | H3: 使用者回報：爬坡坡度 12、速度 4.1 km/h、30 分鐘；獨立記錄，不併入散步分鐘。
A4: 46270 | B4: 跑步機有氧 | C4: 1 | D4: 20 | E4: 1 | F4: 3.3 | H4: 重訓後跑步機有氧；心率約142 bpm。與日常散步分開記錄，也不與12%高坡度爬坡混為同一強度。

Sheet 動作基準
A1: 動作 | B1: 建議下次重量（kg） | C1: 建議目標次數 | D1: 建議DBR | E1: 最近訓練日期 | F1: 最近使用重量（kg） | G1: 最近次數 | H1: 最近DBR | I1: 最近訓練摘要 | J1: 狀態／注意 | K1: 建議依據
A2: 上斜胸推 | C2: 10–15（特殊動作可依既有表現調整） | D2: 1–3；最後一組可視情況 DBR0 | E2: 2026-09-11 | F2: 20 | G2: 12 | H2: 1 | I2: 25kg×15/DBR1；25kg×13/DBR1；25kg×9/DBR0；20kg×12/DBR1 | J2: 疼痛／不適：暫不自動推薦重量 | K2: 最近一次訓練備註出現疼痛／不適；保留歷史重量，但下次先確認無痛，不依重量基準直接加載。
A3: 保加利亞分腿蹲 | B3: 10 | C3: 10–15（特殊動作可依既有表現調整） | D3: 1–3；最後一組可視情況 DBR0 | E3: 2026-09-11 | F3: 10 | G3: 10 | H3: 1 | I3: 左10kg×15/DBR2；左10kg×15/DBR2；左10kg×12/DBR2；左10kg×12/DBR2；左10kg×13/DBR2；右10kg×10/DBR2；左10kg×12/DBR1；右10kg×10/DBR1 | J3: 正常 | K3: 最近一次訓練中 10 kg 有 8 組落在約 8–20 下、DBR1–3；以可重複的工作組表現優先，不直接選最高重量。
A4: 划船 | B4: 26.5 | C4: 10–15（特殊動作可依既有表現調整） | D4: 1–3；最後一組可視情況 DBR0 | E4: 2026-09-07 | F4: 30 | G4: 13 | H4: 0 | I4: 26.5kg×15/DBR4；26.5kg×15/DBR2；30kg×13/DBR2；30kg×13/DBR0；30kg×13/DBR0 | J4: 正常 | K4: 最近一次訓練中 26.5 kg 有 1 組落在約 8–20 下、DBR1–3；以可重複的工作組表現優先，不直接選最高重量。
A5: 反向飛鳥 | B5: 15 | C5: 10–15（特殊動作可依既有表現調整） | D5: 1–3；最後一組可視情況 DBR0 | E5: 2026-09-11 | F5: 15 | G5: 11 | H5: 1 | I5: 15kg×15/DBR3；15kg×15/DBR1；15kg×13/DBR1；15kg×13/DBR1；15kg×11/DBR1 | J5: 正常 | K5: 最近一次訓練中 15 kg 有 5 組落在約 8–20 下、DBR1–3；以可重複的工作組表現優先，不直接選最高重量。
A6: 啞鈴側平舉 | B6: 10 | C6: 10–15（特殊動作可依既有表現調整） | D6: 1–3；最後一組可視情況 DBR0 | E6: 2026-09-07 | F6: 10 | G6: 15 | H6: 0 | I6: 10kg×15/DBR1；10kg×13/DBR1；10kg×14/DBR1；10kg×15/DBR0 | J6: 正常 | K6: 最近一次訓練中 10 kg 有 3 組落在約 8–20 下、DBR1–3；以可重複的工作組表現優先，不直接選最高重量。
A7: 滑輪下拉 | B7: 37.5 | C7: 10–15（特殊動作可依既有表現調整） | D7: 1–3；最後一組可視情況 DBR0 | E7: 2026-09-11 | F7: 37.5 | G7: 8 | H7: 0 | I7: 37.5kg×13/DBR2；37.5kg×13/DBR2；37.5kg×11/DBR1；37.5kg×8/DBR0 | J7: 正常 | K7: 最近一次訓練中 37.5 kg 有 3 組落在約 8–20 下、DBR1–3；以可重複的工作組表現優先，不直接選最高重量。
A8: 睾丸繩下拉 | B8: 6.25 | C8: 10–15（特殊動作可依既有表現調整） | D8: 1–3；最後一組可視情況 DBR0 | E8: 2026-08-14 | F8: 6.25 | G8: 11 | H8: 0 | I8: 8.75kg×11/DBR0；8.75kg×10/DBR0；6.25kg×13/DBR0；6.25kg×13/DBR0；6.25kg×11/DBR0 | J8: 正常 | K8: 最近一次已知組多為力竭；下次採該次較低重量重新建立 DBR1–3 的工作組。
A9: 羅馬尼亞分腿蹲 | B9: 10 | C9: 10–15（特殊動作可依既有表現調整） | D9: 1–3；最後一組可視情況 DBR0 | E9: 2026-09-05 | F9: 10 | G9: 11 | H9: 1 | I9: 左10kg×15/DBR3；右10kg×15/DBR3；左10kg×15/DBR2；右10kg×15/DBR2；左10kg×15/DBR1；右10kg×11/DBR1；左10kg×11/DBR2；右10kg×11/DBR1 | J9: 正常 | K9: 最近一次訓練中 10 kg 有 8 組落在約 8–20 下、DBR1–3；以可重複的工作組表現優先，不直接選最高重量。
A10: 羅馬尼亞蹲 | B10: 5 | C10: 10–15（特殊動作可依既有表現調整） | D10: 1–3；最後一組可視情況 DBR0 | E10: 2026-08-12 | F10: 5 | G10: 14 | H10: 0 | I10: 左自重×15/DBR3；右自重×15/DBR3；左5kg×15/DBR2；右5kg×8/DBR0；左5kg×14/DBR0；右5kg×14/DBR0；左5kg×14/DBR0；右5kg×14/DBR0 | J10: 正常 | K10: 最近一次訓練中 5 kg 有 1 組落在約 8–20 下、DBR1–3；以可重複的工作組表現優先，不直接選最高重量。
A11: 腿內收 | B11: 37.5 | C11: 10–15（特殊動作可依既有表現調整） | D11: 1–3；最後一組可視情況 DBR0 | E11: 2026-09-11 | F11: 37.5 | G11: 13 | H11: 0 | I11: 37.5kg×13/DBR2；37.5kg×13/DBR1；37.5kg×13/DBR1；37.5kg×13/DBR0 | J11: 正常 | K11: 最近一次訓練中 37.5 kg 有 3 組落在約 8–20 下、DBR1–3；以可重複的工作組表現優先，不直接選最高重量。
A12: 腿外展 | B12: 45 | C12: 10–15（特殊動作可依既有表現調整） | D12: 1–3；最後一組可視情況 DBR0 | E12: 2026-09-07 | F12: 45 | G12: 15 | H12: 2 | I12: 40.8kg×15/DBR4；48.75kg×15/DBR1；45kg×15/DBR1；45kg×12/DBR2；45kg×15/DBR2 | J12: 正常 | K12: 最近一次訓練中 45 kg 有 3 組落在約 8–20 下、DBR1–3；以可重複的工作組表現優先，不直接選最高重量。
A13: 腿後勾 | B13: 47 | C13: 10–15（特殊動作可依既有表現調整） | D13: 1–3；最後一組可視情況 DBR0 | E13: 2026-09-07 | F13: 47 | G13: 13 | H13: 0 | I13: 40kg×15/DBR3；47kg×15/DBR1；47kg×12/DBR1；47kg×13/DBR0 | J13: 正常 | K13: 最近一次訓練中 47 kg 有 2 組落在約 8–20 下、DBR1–3；以可重複的工作組表現優先，不直接選最高重量。
A14: 腿推舉 | B14: 40 | C14: 10–15（特殊動作可依既有表現調整） | D14: 1–3；最後一組可視情況 DBR0 | E14: 2026-08-04 | F14: 40 | G14: 16 | H14: 0 | I14: 40kg×16/DBR3；40kg×18/DBR2；40kg×16/DBR1；40kg×16/DBR0 | J14: 正常 | K14: 最近一次訓練中 40 kg 有 3 組落在約 8–20 下、DBR1–3；以可重複的工作組表現優先，不直接選最高重量。
A15: 臀推機 | C15: 10–15（特殊動作可依既有表現調整） | D15: 1–3；最後一組可視情況 DBR0 | E15: 2026-08-28 | F15: 20 | G15: 12 | H15: 2 | I15: 20kg×12/DBR3；20kg×12/DBR2；20kg×12/DBR2 | J15: 疼痛／不適：暫不自動推薦重量 | K15: 最近一次訓練備註出現疼痛／不適；保留歷史重量，但下次先確認無痛，不依重量基準直接加載。
A16: 蝴蝶機夾胸 | B16: 25 | C16: 10–15（特殊動作可依既有表現調整） | D16: 1–3；最後一組可視情況 DBR0 | E16: 2026-08-12 | F16: 20 | G16: 13 | H16: 0 | I16: 25kg×15/DBR3；20kg×15/DBR0；25kg×7/DBR0；20kg×13/DBR0 | J16: 正常 | K16: 最近一次訓練中 25 kg 有 1 組落在約 8–20 下、DBR1–3；以可重複的工作組表現優先，不直接選最高重量。
A17: 飛鳥夾胸 | B17: 20 | C17: 10–15（特殊動作可依既有表現調整） | D17: 1–3；最後一組可視情況 DBR0 | E17: 2026-08-28 | F17: 20 | G17: 10 | H17: 0 | I17: 20kg×15/DBR3；20kg×14/DBR2；20kg×12/DBR1；20kg×10/DBR0 | J17: 正常 | K17: 最近一次訓練中 20 kg 有 3 組落在約 8–20 下、DBR1–3；以可重複的工作組表現優先，不直接選最高重量。
